Workbook
Name Excel_BuiltIn__FilterDatabase: densidade_hab_indL!$A$1:$D$49
Name Excel_BuiltIn__FilterDatabase: rebio23_80ml!$A$3:$CM$104

Sheet contagens
A1: ="n = "&(COUNTA(A6:A1024)) -> n = 68 | B1: TAG | C1: Coleta | D1: Data | E1: Rio | F1: Habitat=Pote | G1: ="Alíquotas = "&SUM(G6:G1024) -> Alíquotas = 54 | H1: ="Amostras = "&SUM(H6:H1024) -> Amostras = 9
A2: PONTO1
A3: PONTO2
A4: PONTO3
A5: PONTO4
A6: PONTO5 | B6: P05-C1-H1 | C6: 2 | D6: 45210 | E6: Barro Branco | F6: 1 | G6: 3 | H6: 0
A7: PONTO5 | B7: P05-C1-H2 | C7: 2 | D7: 45210 | E7: Barro Branco | F7: 2 | G7: 3 | H7: 0
A8: PONTO5 | B8: P05-C1-H3 | C8: 2 | D8: 45210 | E8: Barro Branco | F8: 3 | G8: 3 | H8: 0
A9: PONTO6 | B9: P06-C1-H1 | C9: 2 | D9: 45210 | E9: Barro Branco | F9: 1 | G9: 3 | H9: 0
A10: PONTO6 | B10: P06-C1-H2 | C10: 2 | D10: 45210 | E10: Barro Branco | F10: 2 | G10: 3 | H10: 0
A11: PONTO6 | B11: P06-C1-H3 | C11: 2 | D11: 45210 | E11: Barro Branco | F11: 3 | G11: 3 | H11: 0
A12: PONTO7 | B12: P07-C1-H1 | C12: 2 | D12: 45210 | E12: Barro Branco | F12: 1 | G12: 3 | H12: 0
A13: PONTO7 | B13: P07-C1-H2 | C13: 2 | D13: 45210 | E13: Barro Branco | F13: 2 | G13: 3 | H13: 0
A14: PONTO7 | B14: P07-C1-H3 | C14: 2 | D14: 45210 | E14: Barro Branco | F14: 3 | G14: 3 | H14: 0
A15: PONTO8 | B15: P08-C1-H1 | C15: 1 | D15: 45168 | E15: Barro Branco | F15: 1 | G15: 3 | H15: 0
A16: PONTO8 | B16: P08-C1-H2 | C16: 1 | D16: 45168 | E16: Barro Branco | F16: 2 | G16: 3 | H16: 0
A17: PONTO8 | B17: P08-C1-H3 | C17: 1 | D17: 45168 | E17: Barro Branco | F17: 3 | G17: 3 | H17: 0
... A23: PONTO10 | B23: P010-C1-H3 | C23: 1 | D23: 45168 | E23: Barro Branco | F23: 3 | G23: 3 | H23: 3
A24: PONTO11 | B24: P011-C1-H1 | C24: 5 | D24: 45322 | E24: Caiana | F24: 1
A25: PONTO11 | B25: P011-C1-H2 | C25: 5 | D25: 45322 | E25: Caiana | F25: 2
A26: PONTO11 | B26: P011-C1-H3 | C26: 5 | D26: 45322 | E26: Caiana | F26: 3
A27: PONTO12 | B27: P012-C1-H1 | C27: 5 | D27: 45322 | E27: Caiana | F27: 1
A28: PONTO12 | B28: P012-C1-H2 | C28: 5 | D28: 45322 | E28: Caiana | F28: 2
A29: PONTO12 | B29: P012-C1-H3 | C29: 5 | D29: 45322 | E29: Caiana | F29: 3
A30: PONTO13 | B30: P013-C1-H1 | C30: 5 | D30: 45322 | E30: Caiana | F30: 1
A31: PONTO13 | B31: P013-C1-H2 | C31: 5 | D31: 45322 | E31: Caiana | F31: 2
A32: PONTO13 | B32: P013-C1-H3 | C32: 5 | D32: 45322 | E32: Caiana | F32: 3
A33: PONTO14 | B33: P014-C1-H1 | C33: 5 | D33: 45322 | E33: Caiana | F33: 1
A34: PONTO14 | B34: P014-C1-H2 | C34: 5 | D34: 45322 | E34: Caiana | F34: 2
A35: PONTO14 | B35: P014-C1-H3 | C35: 5 | D35: 45322 | E35: Caiana | F35: 3
... A53: PONTO20 | B53: P020-C1-H3 | C53: 6 | D53: 45343 | E53: Caiana | F53: 3
A54: PONTO21
A55: PONTO22
A56: PONTO23
A57: PONTO24
A58: PONTO25
A59: PONTO26
A60: PONTO27
A61: PONTO28
A62: PONTO29
...

Sheet rebio23_80ml
A1: ="sum= "&SUM(B3:BG50) -> sum= 4420 | B1: Alonella dadayi Birge, 1910 | C1: Alonella hamulata (Birge, 1910) | D1: Alonella sp. | E1: Bdelloidea | F1: Brachionus patulus Müller, 1786 | G1: Cephalodella sp. | H1: Colurella adriatica Ehrenberg, 1831 | I1: Copepodite | J1: Chydorus sp. | K1: Dicranophoroides sp. | L1: Diaphanosoma birgei Korínek, 1981 | M1: Diaphanosoma spinulosum Herbst, 1975 | N1: Dissotrocha aculeata (Ehrenberg, 1832) | O1: Euchlanis dilatata Ehrenberg, 1832 | P1: Filinia longiseta (Ehrenberg, 1834) | Q1: Ilyocryptus spinifer Herrick, 1882 | R1: Lecane aculeata (Jakubski, 1912) | S1: Lecane bulla (Gosse, 1851) | T1: Lecane cornuta (Müller, 1786) | U1: Lecane crepida Murray, 1913 | V1: Lecane curvicornis (Murray, 1913) | W1: Lecane furcata (Murray, 1913) | X1: Lecane haliclysta Harring & Myers, 1926 | Y1: Lecane leontina (Turner, 1892) | Z1: Lecane lunaris (Ehrenberg, 1832) | AA1: Lecane luna (Müller, 1776) | AB1: Lecane monostyla (Daday, 1897) | AC1: Lecane obtusa (Murray, 1913) | AD1: Lecane papuana (Murray, 1913) | AE1: Lecane quadridentata (Ehrenberg, 1832) | AF1: Lecane signifera (Jennings, 1896) | AG1: Leydigia sp. | AH1: Lepadella benjamini Harring, 1916 | AI1: Lepadella imbricata Harring, 1914 | AJ1: Lepadella ovalis (Müller, 1786) | AK1: Lepadella patella (Müller, 1773) | AL1: Mesocyclops sp. | AM1: Macrocyclops sp. | AN1: Macrochaetus sp. | AO1: Macrothrix sp. | AP1: Macrothrix mira (Smirnov, 1992) | AQ1: Macrothrix laticornis (Jurine, 1820) | AR1: Moina minuta Hansen, 1899 | AS1: Mytilina crassipes Wulfert, 1939 | AT1: Mytilina sp. | AU1: Mytilina bisulcata (Lucks, 1912) | AV1: Nauplii | AW1: Notodiaptomus sp. | AX1: Paracyclops sp. | AY1: Platyias quadricornis (Ehrenberg, 1832) | AZ1: Polyarthra sp. | BA1: Polyarthra bicerca Wulfert, 1956 | BB1: Polyarthra dolichoptera Idelson, 1925 | BC1: Polyarthra vulgaris Carlin, 1943 | BD1: Testudinella patina (Hermann, 1783) | BE1: Testudinella mucronata (Gosse, 1886) | BF1: Trichocerca sp. | BG1: Trichotria tetractis (Ehrenberg, 1830)
A2: ="n = "&COUNTA(A3:A1014) -> n = 96 | B2: Alo.dadayi | C2: Alo.hamulata | D2: Alonella.sp | E2: Bdelloidea | F2: Bra.patulus | G2: Cephalodella.sp | H2: Colurella.sp | I2: Copepodite | J2: Chydorus.sp | K2: Dicranophoroides.sp | L2: Dia.birgei | M2: Dia.spinulosum | N2: Dis.aculeata | O2: Euc.dilatata | P2: Fil.longiseta | Q2: Ily.spinifer | R2: Lec.aculeata | S2: Lec.bulla | T2: Lec.cornuta | U2: Lec.crepida | V2: Lec.curvicornis | W2: Lec.furcata | X2: Lecane.sp1 | Y2: Lec.leontina | Z2: Lec.lunaris | AA2: Lec.luna | AB2: Lec.monostyla | AC2: Lecane.sp2 | AD2: Lec.papuana | AE2: Lec.quadridentata | AF2: Lecane.sp3 | AG2: Leydigia.sp | AH2: Lepadella.sp1 | AI2: Lepadella.sp2 | AJ2: Lep.ovalis | AK2: Lep.patella | AL2: Mesocyclops.sp | AM2: Macrocyclops.sp | AN2: Macrochaetus.sp | AO2: Macrothrix.sp | AP2: Mac.mira | AQ2: Mac.laticornis | AR2: Moi.minuta | AS2: Myt.crassipes | AT2: Mytilina.sp | AU2: Myt.bisulcata | AV2: Nauplii | AW2: Notodiaptomus.sp | AX2: Paracyclops.sp | AY2: Pla.quadricornis | AZ2: Polyarthra.sp | BA2: Pol.bicerca | BB2: Pol.dolichoptera | BC2: Pol.vulgaris | BD2: Tes.patina | BE2: Tes.mucronata | BF2: Trichocerca.sp | BG2: Tri.tetractis
A3: S-B-P05-H1 | B3: 0 | C3: 0 | D3: 0 | E3: 37 | F3: 0 | G3: 0 | H3: 0 | I3: 0 | J3: 0 | K3: 0 | L3: 0 | M3: 0 | N3: 0 | O3: 0 | P3: 0 | Q3: 0 | R3: 0 | S3: 1 | T3: 0 | U3: 0 | V3: 0 | W3: 0 | X3: 0 | Y3: 0 | Z3: 0 | AA3: 0 | AB3: 0 | AC3: 0 | AD3: 0 | AE3: 0 | AF3: 0 | AG3: 0 | AH3: 0 | AI3: 0 | AJ3: 0 | AK3: 0 | AL3: 0 | AM3: 0 | AN3: 0 | AO3: 0 | AP3: 0 | AQ3: 0 | AR3: 0 | AS3: 0 | AT3: 0 | AU3: 0 | AV3: 3 | AW3: 0 | AX3: 1 | AY3: 0 | AZ3: 1 | BA3: 0 | BB3: 1 | BC3: 0 | BD3: 0 | BE3: 0 | BF3: 0 | BG3: 0
A4: S-B-P05-H2 | B4: 0 | C4: 0 | D4: 0 | E4: 23 | F4: 0 | G4: 0 | H4: 0 | I4: 4 | J4: 0 | K4: 0 | L4: 0 | M4: 0 | N4: 0 | O4: 0 | P4: 0 | Q4: 0 | R4: 0 | S4: 0 | T4: 0 | U4: 0 | V4: 0 | W4: 0 | X4: 0 | Y4: 0 | Z4: 0 | AA4: 0 | AB4: 0 | AC4: 0 | AD4: 0 | AE4: 0 | AF4: 0 | AG4: 0 | AH4: 0 | AI4: 0 | AJ4: 0 | AK4: 0 | AL4: 0 | AM4: 0 | AN4: 0 | AO4: 1 | AP4: 0 | AQ4: 0 | AR4: 0 | AS4: 0 | AT4: 0 | AU4: 0 | AV4: 0 | AW4: 0 | AX4: 1 | AY4: 0 | AZ4: 0 | BA4: 0 | BB4: 0 | BC4: 0 | BD4: 0 | BE4: 0 | BF4: 0 | BG4: 0
A5: S-B-P05-H3 | B5: 0 | C5: 0 | D5: 0 | E5: 32 | F5: 0 | G5: 0 | H5: 0 | I5: 2 | J5: 0 | K5: 0 | L5: 0 | M5: 0 | N5: 0 | O5: 0 | P5: 0 | Q5: 0 | R5: 0 | S5: 2 | T5: 0 | U5: 0 | V5: 0 | W5: 0 | X5: 0 | Y5: 0 | Z5: 0 | AA5: 0 | AB5: 0 | AC5: 0 | AD5: 0 | AE5: 0 | AF5: 0 | AG5: 0 | AH5: 0 | AI5: 0 | AJ5: 0 | AK5: 0 | AL5: 0 | AM5: 0 | AN5: 0 | AO5: 0 | AP5: 0 | AQ5: 0 | AR5: 0 | AS5: 0 | AT5: 0 | AU5: 0 | AV5: 6 | AW5: 0 | AX5: 0 | AY5: 0 | AZ5: 0 | BA5: 0 | BB5: 0 | BC5: 0 | BD5: 0 | BE5: 0 | BF5: 0 | BG5: 0
A6: S-B-P06-H1 | B6: 0 | C6: 0 | D6: 0 | E6: 32 | F6: 0 | G6: 0 | H6: 0 | I6: 0 | J6: 0 | K6: 0 | L6: 0 | M6: 0 | N6: 0 | O6: 0 | P6: 0 | Q6: 0 | R6: 0 | S6: 0 | T6: 0 | U6: 0 | V6: 0 | W6: 0 | X6: 0 | Y6: 0 | Z6: 0 | AA6: 0 | AB6: 0 | AC6: 0 | AD6: 0 | AE6: 0 | AF6: 0 | AG6: 0 | AH6: 0 | AI6: 0 | AJ6: 0 | AK6: 0 | AL6: 0 | AM6: 0 | AN6: 0 | AO6: 0 | AP6: 0 | AQ6: 0 | AR6: 0 | AS6: 0 | AT6: 0 | AU6: 0 | AV6: 0 | AW6: 0 | AX6: 0 | AY6: 0 | AZ6: 0 | BA6: 0 | BB6: 0 | BC6: 0 | BD6: 0 | BE6: 0 | BF6: 0 | BG6: 0
A7: S-B-P06-H2 | B7: 1 | C7: 0 | D7: 0 | E7: 64 | F7: 0 | G7: 0 | H7: 0 | I7: 1 | J7: 0 | K7: 0 | L7: 0 | M7: 0 | N7: 0 | O7: 0 | P7: 0 | Q7: 0 | R7: 0 | S7: 0 | T7: 0 | U7: 0 | V7: 0 | W7: 0 | X7: 0 | Y7: 0 | Z7: 0 | AA7: 0 | AB7: 0 | AC7: 0 | AD7: 0 | AE7: 0 | AF7: 0 | AG7: 0 | AH7: 0 | AI7: 0 | AJ7: 0 | AK7: 0 | AL7: 0 | AM7: 0 | AN7: 0 | AO7: 0 | AP7: 0 | AQ7: 0 | AR7: 0 | AS7: 0 | AT7: 0 | AU7: 0 | AV7: 1 | AW7: 0 | AX7: 0 | AY7: 0 | AZ7: 0 | BA7: 0 | BB7: 0 | BC7: 0 | BD7: 0 | BE7: 0 | BF7: 0 | BG7: 0
A8: S-B-P06-H3 | B8: 0 | C8: 0 | D8: 0 | E8: 77 | F8: 0 | G8: 0 | H8: 0 | I8: 0 | J8: 0 | K8: 0 | L8: 0 | M8: 0 | N8: 0 | O8: 0 | P8: 0 | Q8: 0 | R8: 0 | S8: 0 | T8: 0 | U8: 0 | V8: 0 | W8: 0 | X8: 0 | Y8: 0 | Z8: 0 | AA8: 0 | AB8: 0 | AC8: 0 | AD8: 0 | AE8: 0 | AF8: 0 | AG8: 0 | AH8: 0 | AI8: 0 | AJ8: 0 | AK8: 0 | AL8: 0 | AM8: 0 | AN8: 0 | AO8: 0 | AP8: 0 | AQ8: 0 | AR8: 0 | AS8: 0 | AT8: 0 | AU8: 0 | AV8: 3 | AW8: 0 | AX8: 0 | AY8: 0 | AZ8: 0 | BA8: 0 | BB8: 0 | BC8: 0 | BD8: 0 | BE8: 0 | BF8: 0 | BG8: 0
A9: S-B-P07-H1 | B9: 0 | C9: 0 | D9: 0 | E9: 59 | F9: 0 | G9: 0 | H9: 0 | I9: 2 | J9: 0 | K9: 0 | L9: 0 | M9: 0 | N9: 0 | O9: 0 | P9: 0 | Q9: 0 | R9: 0 | S9: 0 | T9: 0 | U9: 0 | V9: 0 | W9: 0 | X9: 0 | Y9: 0 | Z9: 0 | AA9: 0 | AB9: 0 | AC9: 0 | AD9: 0 | AE9: 0 | AF9: 0 | AG9: 0 | AH9: 0 | AI9: 0 | AJ9: 0 | AK9: 0 | AL9: 0 | AM9: 0 | AN9: 0 | AO9: 0 | AP9: 0 | AQ9: 0 | AR9: 0 | AS9: 0 | AT9: 0 | AU9: 0 | AV9: 1 | AW9: 0 | AX9: 0 | AY9: 0 | AZ9: 0 | BA9: 0 | BB9: 0 | BC9: 0 | BD9: 0 | BE9: 0 | BF9: 0 | BG9: 0
A10: S-B-P07-H2 | B10: 0 | C10: 0 | D10: 0 | E10: 44 | F10: 0 | G10: 0 | H10: 0 | I10: 0 | J10: 0 | K10: 0 | L10: 0 | M10: 0 | N10: 0 | O10: 0 | P10: 0 | Q10: 0 | R10: 0 | S10: 0 | T10: 0 | U10: 0 | V10: 0 | W10: 0 | X10: 0 | Y10: 0 | Z10: 0 | AA10: 0 | AB10: 0 | AC10: 0 | AD10: 0 | AE10: 0 | AF10: 0 | AG10: 0 | AH10: 0 | AI10: 0 | AJ10: 0 | AK10: 0 | AL10: 0 | AM10: 0 | AN10: 0 | AO10: 0 | AP10: 0 | AQ10: 0 | AR10: 0 | AS10: 0 | AT10: 0 | AU10: 0 | AV10: 2 | AW10: 0 | AX10: 1 | AY10: 0 | AZ10: 1 | BA10: 0 | BB10: 0 | BC10: 0 | BD10: 0 | BE10: 0 | BF10: 0 | BG10: 0
A11: S-B-P07-H3 | B11: 0 | C11: 0 | D11: 0 | E11: 43 | F11: 0 | G11: 0 | H11: 0 | I11: 0 | J11: 0 | K11: 0 | L11: 0 | M11: 0 | N11: 0 | O11: 0 | P11: 0 | Q11: 0 | R11: 0 | S11: 1 | T11: 0 | U11: 0 | V11: 0 | W11: 0 | X11: 0 | Y11: 0 | Z11: 0 | AA11: 0 | AB11: 0 | AC11: 0 | AD11: 0 | AE11: 0 | AF11: 1 | AG11: 0 | AH11: 0 | AI11: 0 | AJ11: 0 | AK11: 0 | AL11: 0 | AM11: 0 | AN11: 0 | AO11: 0 | AP11: 0 | AQ11: 0 | AR11: 0 | AS11: 0 | AT11: 0 | AU11: 0 | AV11: 4 | AW11: 0 | AX11: 0 | AY11: 0 | AZ11: 1 | BA11: 0 | BB11: 0 | BC11: 0 | BD11: 0 | BE11: 0 | BF11: 0 | BG11: 0
A12: S-B-P08-H1 | B12: 1 | C12: 0 | D12: 0 | E12: 69 | F12: 0 | G12: 0 | H12: 1 | I12: 76 | J12: 0 | K12: 0 | L12: 0 | M12: 0 | N12: 0 | O12: 0 | P12: 1 | Q12: 1 | R12: 0 | S12: 0 | T12: 0 | U12: 0 | V12: 0 | W12: 0 | X12: 1 | Y12: 1 | Z12: 0 | AA12: 4 | AB12: 0 | AC12: 0 | AD12: 0 | AE12: 0 | AF12: 0 | AG12: 0 | AH12: 0 | AI12: 0 | AJ12: 0 | AK12: 0 | AL12: 3 | AM12: 2 | AN12: 0 | AO12: 0 | AP12: 0 | AQ12: 0 | AR12: 0 | AS12: 0 | AT12: 0 | AU12: 1 | AV12: 15 | AW12: 0 | AX12: 9 | AY12: 0 | AZ12: 0 | BA12: 0 | BB12: 1 | BC12: 0 | BD12: 0 | BE12: 0 | BF12: 0 | BG12: 0
A13: S-B-P08-H2 | B13: 6 | C13: 0 | D13: 0 | E13: 50 | F13: 0 | G13: 0 | H13: 0 | I13: 77 | J13: 0 | K13: 0 | L13: 0 | M13: 0 | N13: 0 | O13: 0 | P13: 0 | Q13: 0 | R13: 0 | S13: 8 | T13: 0 | U13: 4 | V13: 0 | W13: 0 | X13: 0 | Y13: 0 | Z13: 2 | AA13: 2 | AB13: 0 | AC13: 0 | AD13: 0 | AE13: 1 | AF13: 0 | AG13: 0 | AH13: 0 | AI13: 0 | AJ13: 2 | AK13: 0 | AL13: 1 | AM13: 0 | AN13: 0 | AO13: 0 | AP13: 0 | AQ13: 0 | AR13: 0 | AS13: 0 | AT13: 0 | AU13: 0 | AV13: 60 | AW13: 0 | AX13: 4 | AY13: 0 | AZ13: 0 | BA13: 0 | BB13: 0 | BC13: 0 | BD13: 0 | BE13: 0 | BF13: 0 | BG13: 0
A14: S-B-P08-H3 | B14: 1 | C14: 0 | D14: 0 | E14: 51 | F14: 0 | G14: 0 | H14: 0 | I14: 3 | J14: 0 | K14: 0 | L14: 0 | M14: 0 | N14: 0 | O14: 0 | P14: 0 | Q14: 0 | R14: 0 | S14: 2 | T14: 0 | U14: 1 | V14: 1 | W14: 0 | X14: 0 | Y14: 0 | Z14: 0 | AA14: 4 | AB14: 1 | AC14: 0 | AD14: 2 | AE14: 1 | AF14: 0 | AG14: 0 | AH14: 0 | AI14: 0 | AJ14: 0 | AK14: 0 | AL14: 0 | AM14: 0 | AN14: 0 | AO14: 0 | AP14: 1 | AQ14: 0 | AR14: 0 | AS14: 0 | AT14: 0 | AU14: 0 | AV14: 15 | AW14: 0 | AX14: 1 | AY14: 0 | AZ14: 0 | BA14: 0 | BB14: 0 | BC14: 0 | BD14: 0 | BE14: 0 | BF14: 0 | BG14: 0
... A98: C-C-P20-H3 | B98: 0 | C98: 0 | D98: 0 | E98: 50 | F98: 0 | G98: 0 | H98: 0 | I98: 1 | J98: 0 | K98: 0 | L98: 0 | M98: 0 | N98: 0 | O98: 0 | P98: 0 | Q98: 0 | R98: 0 | S98: 0 | T98: 0 | U98: 0 | V98: 0 | W98: 0 | X98: 0 | Y98: 0 | Z98: 0 | AA98: 0 | AB98: 0 | AC98: 0 | AD98: 0 | AE98: 0 | AF98: 0 | AG98: 0 | AH98: 0 | AI98: 0 | AJ98: 0 | AK98: 0 | AL98: 0 | AM98: 0 | AN98: 0 | AO98: 0 | AP98: 0 | AQ98: 0 | AR98: 0 | AS98: 0 | AT98: 0 | AU98: 0 | AV98: 0 | AW98: 0 | AX98: 0 | AY98: 0 | AZ98: 0 | BA98: 0 | BB98: 0 | BC98: 0 | BD98: 0 | BE98: 0 | BF98: 0 | BG98: 0

Sheet densidade_hab_indL
B1: =rebio23_80ml!B2 -> Alo.dadayi | C1: =rebio23_80ml!C2 -> Alo.hamulata | D1: =rebio23_80ml!D2 -> Alonella.sp | E1: =rebio23_80ml!E2 -> Bdelloidea | F1: =rebio23_80ml!F2 -> Bra.patulus | G1: =rebio23_80ml!G2 -> Cephalodella.sp | H1: =rebio23_80ml!H2 -> Colurella.sp | I1: =rebio23_80ml!I2 -> Copepodite | ... BG1: =rebio23_80ml!BG2 -> Tri.tetractis
A2: =rebio23_80ml!A3 -> S-B-P05-H1 | B2: =rebio23_80ml!B3/50 -> 0 | C2: =rebio23_80ml!C3/50 -> 0 | D2: =rebio23_80ml!D3/50 -> 0 | E2: =rebio23_80ml!E3/50 -> 0.74 | F2: =rebio23_80ml!F3/50 -> 0 | G2: =rebio23_80ml!G3/50 -> 0 | H2: =rebio23_80ml!H3/50 -> 0 | I2: =rebio23_80ml!I3/50 -> 0 | ... BG2: =rebio23_80ml!BG3/50 -> 0
A3: =rebio23_80ml!A4 -> S-B-P05-H2 | B3: =rebio23_80ml!B4/50 -> 0 | C3: =rebio23_80ml!C4/50 -> 0 | D3: =rebio23_80ml!D4/50 -> 0 | E3: =rebio23_80ml!E4/50 -> 0.46 | F3: =rebio23_80ml!F4/50 -> 0 | G3: =rebio23_80ml!G4/50 -> 0 | H3: =rebio23_80ml!H4/50 -> 0 | I3: =rebio23_80ml!I4/50 -> 0.08 | ... BG3: =rebio23_80ml!BG4/50 -> 0
A4: =rebio23_80ml!A5 -> S-B-P05-H3 | B4: =rebio23_80ml!B5/50 -> 0 | C4: =rebio23_80ml!C5/50 -> 0 | D4: =rebio23_80ml!D5/50 -> 0 | E4: =rebio23_80ml!E5/50 -> 0.64 | F4: =rebio23_80ml!F5/50 -> 0 | G4: =rebio23_80ml!G5/50 -> 0 | H4: =rebio23_80ml!H5/50 -> 0 | I4: =rebio23_80ml!I5/50 -> 0.04 | ... BG4: =rebio23_80ml!BG5/50 -> 0
A5: =rebio23_80ml!A6 -> S-B-P06-H1 | B5: =rebio23_80ml!B6/50 -> 0 | C5: =rebio23_80ml!C6/50 -> 0 | D5: =rebio23_80ml!D6/50 -> 0 | E5: =rebio23_80ml!E6/50 -> 0.64 | F5: =rebio23_80ml!F6/50 -> 0 | G5: =rebio23_80ml!G6/50 -> 0 | H5: =rebio23_80ml!H6/50 -> 0 | I5: =rebio23_80ml!I6/50 -> 0 | ... BG5: =rebio23_80ml!BG6/50 -> 0
A6: =rebio23_80ml!A7 -> S-B-P06-H2 | B6: =rebio23_80ml!B7/50 -> 0.02 | C6: =rebio23_80ml!C7/50 -> 0 | D6: =rebio23_80ml!D7/50 -> 0 | E6: =rebio23_80ml!E7/50 -> 1.28 | F6: =rebio23_80ml!F7/50 -> 0 | G6: =rebio23_80ml!G7/50 -> 0 | H6: =rebio23_80ml!H7/50 -> 0 | I6: =rebio23_80ml!I7/50 -> 0.02 | ... BG6: =rebio23_80ml!BG7/50 -> 0
A7: =rebio23_80ml!A8 -> S-B-P06-H3 | B7: =rebio23_80ml!B8/50 -> 0 | C7: =rebio23_80ml!C8/50 -> 0 | D7: =rebio23_80ml!D8/50 -> 0 | E7: =rebio23_80ml!E8/50 -> 1.54 | F7: =rebio23_80ml!F8/50 -> 0 | G7: =rebio23_80ml!G8/50 -> 0 | H7: =rebio23_80ml!H8/50 -> 0 | I7: =rebio23_80ml!I8/50 -> 0 | ... BG7: =rebio23_80ml!BG8/50 -> 0
A8: =rebio23_80ml!A9 -> S-B-P07-H1 | B8: =rebio23_80ml!B9/50 -> 0 | C8: =rebio23_80ml!C9/50 -> 0 | D8: =rebio23_80ml!D9/50 -> 0 | E8: =rebio23_80ml!E9/50 -> 1.18 | F8: =rebio23_80ml!F9/50 -> 0 | G8: =rebio23_80ml!G9/50 -> 0 | H8: =rebio23_80ml!H9/50 -> 0 | I8: =rebio23_80ml!I9/50 -> 0.04 | ... BG8: =rebio23_80ml!BG9/50 -> 0
A9: =rebio23_80ml!A10 -> S-B-P07-H2 | B9: =rebio23_80ml!B10/50 -> 0 | C9: =rebio23_80ml!C10/50 -> 0 | D9: =rebio23_80ml!D10/50 -> 0 | E9: =rebio23_80ml!E10/50 -> 0.88 | F9: =rebio23_80ml!F10/50 -> 0 | G9: =rebio23_80ml!G10/50 -> 0 | H9: =rebio23_80ml!H10/50 -> 0 | I9: =rebio23_80ml!I10/50 -> 0 | ... BG9: =rebio23_80ml!BG10/50 -> 0
A10: =rebio23_80ml!A11 -> S-B-P07-H3 | B10: =rebio23_80ml!B11/50 -> 0 | C10: =rebio23_80ml!C11/50 -> 0 | D10: =rebio23_80ml!D11/50 -> 0 | E10: =rebio23_80ml!E11/50 -> 0.86 | F10: =rebio23_80ml!F11/50 -> 0 | G10: =rebio23_80ml!G11/50 -> 0 | H10: =rebio23_80ml!H11/50 -> 0 | I10: =rebio23_80ml!I11/50 -> 0 | ... BG10: =rebio23_80ml!BG11/50 -> 0
A11: =rebio23_80ml!A12 -> S-B-P08-H1 | B11: =rebio23_80ml!B12/50 -> 0.02 | C11: =rebio23_80ml!C12/50 -> 0 | D11: =rebio23_80ml!D12/50 -> 0 | E11: =rebio23_80ml!E12/50 -> 1.38 | F11: =rebio23_80ml!F12/50 -> 0 | G11: =rebio23_80ml!G12/50 -> 0 | H11: =rebio23_80ml!H12/50 -> 0.02 | I11: =rebio23_80ml!I12/50 -> 1.52 | ... BG11: =rebio23_80ml!BG12/50 -> 0
A12: =rebio23_80ml!A13 -> S-B-P08-H2 | B12: =rebio23_80ml!B13/50 -> 0.12 | C12: =rebio23_80ml!C13/50 -> 0 | D12: =rebio23_80ml!D13/50 -> 0 | E12: =rebio23_80ml!E13/50 -> 1 | F12: =rebio23_80ml!F13/50 -> 0 | G12: =rebio23_80ml!G13/50 -> 0 | H12: =rebio23_80ml!H13/50 -> 0 | I12: =rebio23_80ml!I13/50 -> 1.54 | ... BG12: =rebio23_80ml!BG13/50 -> 0
A13: =rebio23_80ml!A14 -> S-B-P08-H3 | B13: =rebio23_80ml!B14/50 -> 0.02 | C13: =rebio23_80ml!C14/50 -> 0 | D13: =rebio23_80ml!D14/50 -> 0 | E13: =rebio23_80ml!E14/50 -> 1.02 | F13: =rebio23_80ml!F14/50 -> 0 | G13: =rebio23_80ml!G14/50 -> 0 | H13: =rebio23_80ml!H14/50 -> 0 | I13: =rebio23_80ml!I14/50 -> 0.06 | ... BG13: =rebio23_80ml!BG14/50 -> 0
... A60: =rebio23_80ml!A61 -> C-B-P08-H2 | B60: =rebio23_80ml!B61/50 -> 3.16 | C60: =rebio23_80ml!C61/50 -> 0.62 | D60: =rebio23_80ml!D61/50 -> 0.2 | E60: =rebio23_80ml!E61/50 -> 3.94 | F60: =rebio23_80ml!F61/50 -> 0.02 | G60: =rebio23_80ml!G61/50 -> 0 | H60: =rebio23_80ml!H61/50 -> 0 | I60: =rebio23_80ml!I61/50 -> 8.14 | ... BG60: =rebio23_80ml!BG61/50 -> 0
A61: =rebio23_80ml!A62 -> C-B-P08-H3 | B61: =rebio23_80ml!B62/50 -> 0.02 | C61: =rebio23_80ml!C62/50 -> 0 | D61: =rebio23_80ml!D62/50 -> 0 | E61: =rebio23_80ml!E62/50 -> 2.52 | F61: =rebio23_80ml!F64/50 -> 0 | G61: =rebio23_80ml!G62/50 -> 0 | H61: =rebio23_80ml!H62/50 -> 0 | I61: =rebio23_80ml!I62/50 -> 0.1 | J61: =rebio23_80ml!J62/50 -> 0 | K61: =rebio23_80ml!K62/50 -> 0 | L61: =rebio23_80ml!L62/50 -> 0.02 | M61: =rebio23_80ml!M62/50 -> 0 | N61: =rebio23_80ml!N62/50 -> 0 | ... BG61: =rebio23_80ml!BG62/50 -> 0
A62: =rebio23_80ml!A63 -> C-B-P09-H1 | B62: =rebio23_80ml!B63/50 -> 0 | C62: =rebio23_80ml!C63/50 -> 0 | D62: =rebio23_80ml!D63/50 -> 0 | E62: =rebio23_80ml!E63/50 -> 1.48 | F62: =rebio23_80ml!F65/50 -> 0 | G62: =rebio23_80ml!G63/50 -> 0 | H62: =rebio23_80ml!H63/50 -> 0 | I62: =rebio23_80ml!I63/50 -> 0 | J62: =rebio23_80ml!J63/50 -> 0 | K62: =rebio23_80ml!K63/50 -> 0 | L62: =rebio23_80ml!L63/50 -> 0 | M62: =rebio23_80ml!M63/50 -> 0 | N62: =rebio23_80ml!N63/50 -> 0 | ... BG62: =rebio23_80ml!BG63/50 -> 0
A63: =rebio23_80ml!A64 -> C-B-P09-H2 | B63: =rebio23_80ml!B64/50 -> 0.02 | C63: =rebio23_80ml!C64/50 -> 0 | D63: =rebio23_80ml!D64/50 -> 0 | E63: =rebio23_80ml!E64/50 -> 1.56 | F63: =rebio23_80ml!F64/50 -> 0 | G63: =rebio23_80ml!G64/50 -> 0 | H63: =rebio23_80ml!H64/50 -> 0 | I63: =rebio23_80ml!I64/50 -> 0 | ... BG63: =rebio23_80ml!BG64/50 -> 0
A64: =rebio23_80ml!A65 -> C-B-P09-H3 | B64: =rebio23_80ml!B65/50 -> 0.02 | C64: =rebio23_80ml!C65/50 -> 0.04 | D64: =rebio23_80ml!D65/50 -> 0 | E64: =rebio23_80ml!E65/50 -> 2.98 | F64: =rebio23_80ml!F65/50 -> 0 | G64: =rebio23_80ml!G65/50 -> 0 | H64: =rebio23_80ml!H65/50 -> 0 | I64: =rebio23_80ml!I65/50 -> 0 | ... BG64: =rebio23_80ml!BG65/50 -> 0
A65: =rebio23_80ml!A66 -> C-B-P10-H1 | B65: =rebio23_80ml!B66/50 -> 0.14 | C65: =rebio23_80ml!C66/50 -> 0 | D65: =rebio23_80ml!D66/50 -> 0 | E65: =rebio23_80ml!E66/50 -> 2.1 | F65: =rebio23_80ml!F66/50 -> 0 | G65: =rebio23_80ml!G66/50 -> 0 | H65: =rebio23_80ml!H66/50 -> 0 | I65: =rebio23_80ml!I66/50 -> 0.04 | ... BG65: =rebio23_80ml!BG66/50 -> 0
A66: =rebio23_80ml!A67 -> C-B-P10-H2 | B66: =rebio23_80ml!B67/50 -> 0.22 | C66: =rebio23_80ml!C67/50 -> 0.02 | D66: =rebio23_80ml!D67/50 -> 0.04 | E66: =rebio23_80ml!E67/50 -> 2.32 | F66: =rebio23_80ml!F67/50 -> 0 | G66: =rebio23_80ml!G67/50 -> 0.02 | H66: =rebio23_80ml!H67/50 -> 0 | I66: =rebio23_80ml!I67/50 -> 0.16 | ... BG66: =rebio23_80ml!BG67/50 -> 0
A67: =rebio23_80ml!A68 -> C-B-P10-H3 | B67: =rebio23_80ml!B68/50 -> 0.72 | C67: =rebio23_80ml!C68/50 -> 0.16 | D67: =rebio23_80ml!D68/50 -> 0.1 | E67: =rebio23_80ml!E68/50 -> 4.4 | F67: =rebio23_80ml!F68/50 -> 0.04 | G67: =rebio23_80ml!G68/50 -> 0.14 | H67: =rebio23_80ml!H68/50 -> 0 | I67: =rebio23_80ml!I68/50 -> 1.4 | ... BG67: =rebio23_80ml!BG68/50 -> 0
A68: =rebio23_80ml!A69 -> C-C-P11-H1 | B68: =rebio23_80ml!B69/50 -> 0 | C68: =rebio23_80ml!C69/50 -> 0 | D68: =rebio23_80ml!D69/50 -> 0 | E68: =rebio23_80ml!E69/50 -> 0 | F68: =rebio23_80ml!F69/50 -> 0 | G68: =rebio23_80ml!G69/50 -> 0 | H68: =rebio23_80ml!H69/50 -> 0 | I68: =rebio23_80ml!I69/50 -> 0 | ... BG68: =rebio23_80ml!BG69/50 -> 0
A69: =rebio23_80ml!A70 -> C-C-P11-H2 | B69: =rebio23_80ml!B70/50 -> 0 | C69: =rebio23_80ml!C70/50 -> 0 | D69: =rebio23_80ml!D70/50 -> 0 | E69: =rebio23_80ml!E70/50 -> 0 | F69: =rebio23_80ml!F70/50 -> 0 | G69: =rebio23_80ml!G70/50 -> 0 | H69: =rebio23_80ml!H70/50 -> 0 | I69: =rebio23_80ml!I70/50 -> 0 | ... BG69: =rebio23_80ml!BG70/50 -> 0
A70: =rebio23_80ml!A71 -> C-C-P11-H3 | B70: =rebio23_80ml!B71/50 -> 0 | C70: =rebio23_80ml!C71/50 -> 0 | D70: =rebio23_80ml!D71/50 -> 0 | E70: =rebio23_80ml!E71/50 -> 0 | F70: =rebio23_80ml!F71/50 -> 0 | G70: =rebio23_80ml!G71/50 -> 0 | H70: =rebio23_80ml!H71/50 -> 0 | I70: =rebio23_80ml!I71/50 -> 0 | ... BG70: =rebio23_80ml!BG71/50 -> 0
A71: =rebio23_80ml!A72 -> C-C-P12-H1 | B71: =rebio23_80ml!B72/50 -> 0.06 | C71: =rebio23_80ml!C72/50 -> 0 | D71: =rebio23_80ml!D72/50 -> 0 | E71: =rebio23_80ml!E72/50 -> 2.62 | F71: =rebio23_80ml!F72/50 -> 0 | G71: =rebio23_80ml!G72/50 -> 0 | H71: =rebio23_80ml!H72/50 -> 0 | I71: =rebio23_80ml!I72/50 -> 0.2 | ... BG71: =rebio23_80ml!BG72/50 -> 0
A72: =rebio23_80ml!A73 -> C-C-P12-H2 | B72: =rebio23_80ml!B73/50 -> 0.04 | C72: =rebio23_80ml!C73/50 -> 0 | D72: =rebio23_80ml!D73/50 -> 0 | E72: =rebio23_80ml!E73/50 -> 4.18 | F72: =rebio23_80ml!F73/50 -> 0 | G72: =rebio23_80ml!G73/50 -> 0 | H72: =rebio23_80ml!H73/50 -> 0 | I72: =rebio23_80ml!I73/50 -> 0.06 | ... BG72: =rebio23_80ml!BG73/50 -> 0
A73: =rebio23_80ml!A74 -> C-C-P12-H3 | B73: =rebio23_80ml!B74/50 -> 0.1 | C73: =rebio23_80ml!C74/50 -> 0 | D73: =rebio23_80ml!D74/50 -> 0 | E73: =rebio23_80ml!E74/50 -> 3.16 | F73: =rebio23_80ml!F74/50 -> 0 | G73: =rebio23_80ml!G74/50 -> 0 | H73: =rebio23_80ml!H74/50 -> 0 | I73: =rebio23_80ml!I74/50 -> 0.08 | ... BG73: =rebio23_80ml!BG74/50 -> 0
A74: =rebio23_80ml!A75 -> C-C-P13-H1 | B74: =rebio23_80ml!B75/50 -> 0.1 | C74: =rebio23_80ml!C75/50 -> 0 | D74: =rebio23_80ml!D75/50 -> 0 | E74: =rebio23_80ml!E75/50 -> 2.14 | F74: =rebio23_80ml!F75/50 -> 0.02 | G74: =rebio23_80ml!G75/50 -> 0 | H74: =rebio23_80ml!H75/50 -> 0 | I74: =rebio23_80ml!I75/50 -> 0.28 | ... BG74: =rebio23_80ml!BG75/50 -> 0
... A97: =rebio23_80ml!A98 -> C-C-P20-H3 | B97: =rebio23_80ml!B98/50 -> 0 | C97: =rebio23_80ml!C98/50 -> 0 | D97: =rebio23_80ml!D98/50 -> 0 | E97: =rebio23_80ml!E98/50 -> 1 | F97: =rebio23_80ml!F98/50 -> 0 | G97: =rebio23_80ml!G98/50 -> 0 | H97: =rebio23_80ml!H98/50 -> 0 | I97: =rebio23_80ml!I98/50 -> 0.02 | ... BG97: =rebio23_80ml!BG98/50 -> 0

Sheet densidade_ponto_indL
B1: =rebio23_80ml!B2 -> Alo.dadayi | C1: =rebio23_80ml!C2 -> Alo.hamulata | D1: =rebio23_80ml!D2 -> Alonella.sp | E1: =rebio23_80ml!E2 -> Bdelloidea | F1: =rebio23_80ml!F2 -> Bra.patulus | G1: =rebio23_80ml!G2 -> Cephalodella.sp | H1: =rebio23_80ml!H2 -> Colurella.sp | I1: =rebio23_80ml!I2 -> Copepodite | ... BG1: =rebio23_80ml!BG2 -> Tri.tetractis
A2: S-BB-P05 | B2: =AVERAGE(densidade_hab_indL!B2:B4) -> 0 | C2: =AVERAGE(densidade_hab_indL!C2:C4) -> 0 | D2: =AVERAGE(densidade_hab_indL!D2:D4) -> 0 | E2: =AVERAGE(densidade_hab_indL!E2:E4) -> 0.61333333 | F2: =AVERAGE(densidade_hab_indL!F2:F4) -> 0 | G2: =AVERAGE(densidade_hab_indL!G2:G4) -> 0 | H2: =AVERAGE(densidade_hab_indL!H2:H4) -> 0 | I2: =AVERAGE(densidade_hab_indL!I2:I4) -> 0.04 | ... BG2: =AVERAGE(densidade_hab_indL!BG2:BG4) -> 0
A3: S-BB-P06 | B3: =AVERAGE(densidade_hab_indL!B5:B7) -> 0.0066666667 | C3: =AVERAGE(densidade_hab_indL!C5:C7) -> 0 | D3: =AVERAGE(densidade_hab_indL!D5:D7) -> 0 | E3: =AVERAGE(densidade_hab_indL!E5:E7) -> 1.1533333 | F3: =AVERAGE(densidade_hab_indL!F5:F7) -> 0 | G3: =AVERAGE(densidade_hab_indL!G5:G7) -> 0 | H3: =AVERAGE(densidade_hab_indL!H5:H7) -> 0 | I3: =AVERAGE(densidade_hab_indL!I5:I7) -> 0.0066666667 | ... BG3: =AVERAGE(densidade_hab_indL!BG5:BG7) -> 0
A4: S-BB-P07 | B4: =AVERAGE(densidade_hab_indL!B8:B10) -> 0 | C4: =AVERAGE(densidade_hab_indL!C8:C10) -> 0 | D4: =AVERAGE(densidade_hab_indL!D8:D10) -> 0 | E4: =AVERAGE(densidade_hab_indL!E8:E10) -> 0.97333333 | F4: =AVERAGE(densidade_hab_indL!F8:F10) -> 0 | G4: =AVERAGE(densidade_hab_indL!G8:G10) -> 0 | H4: =AVERAGE(densidade_hab_indL!H8:H10) -> 0 | I4: =AVERAGE(densidade_hab_indL!I8:I10) -> 0.013333333 | ... BG4: =AVERAGE(densidade_hab_indL!BG8:BG10) -> 0
A5: S-BB-P08 | B5: =AVERAGE(densidade_hab_indL!B11:B13) -> 0.053333333 | C5: =AVERAGE(densidade_hab_indL!C11:C13) -> 0 | D5: =AVERAGE(densidade_hab_indL!D11:D13) -> 0 | E5: =AVERAGE(densidade_hab_indL!E11:E13) -> 1.1333333 | F5: =AVERAGE(densidade_hab_indL!F11:F13) -> 0 | G5: =AVERAGE(densidade_hab_indL!G11:G13) -> 0 | H5: =AVERAGE(densidade_hab_indL!H11:H13) -> 0.0066666667 | I5: =AVERAGE(densidade_hab_indL!I11:I13) -> 1.04 | ... BG5: =AVERAGE(densidade_hab_indL!BG11:BG13) -> 0
A6: S-BB-P09 | B6: =AVERAGE(densidade_hab_indL!B14:B16) -> 0 | C6: =AVERAGE(densidade_hab_indL!C14:C16) -> 0 | D6: =AVERAGE(densidade_hab_indL!D14:D16) -> 0 | E6: =AVERAGE(densidade_hab_indL!E14:E16) -> 1.4866667 | F6: =AVERAGE(densidade_hab_indL!F14:F16) -> 0 | G6: =AVERAGE(densidade_hab_indL!G14:G16) -> 0 | H6: =AVERAGE(densidade_hab_indL!H14:H16) -> 0.013333333 | I6: =AVERAGE(densidade_hab_indL!I14:I16) -> 0.0066666667 | ... BG6: =AVERAGE(densidade_hab_indL!BG14:BG16) -> 0
A7: S-BB-P10 | B7: =AVERAGE(densidade_hab_indL!B17:B19) -> 0.026666667 | C7: =AVERAGE(densidade_hab_indL!C17:C19) -> 0 | D7: =AVERAGE(densidade_hab_indL!D17:D19) -> 0 | E7: =AVERAGE(densidade_hab_indL!E17:E19) -> 1.2666667 | F7: =AVERAGE(densidade_hab_indL!F17:F19) -> 0.02 | G7: =AVERAGE(densidade_hab_indL!G17:G19) -> 0.013333333 | H7: =AVERAGE(densidade_hab_indL!H17:H19) -> 0.033333333 | I7: =AVERAGE(densidade_hab_indL!I17:I19) -> 0.0066666667 | ... BG7: =AVERAGE(densidade_hab_indL!BG17:BG19) -> 0.013333333
A8: S-CA-P11 | B8: n/a | C8: n/a | D8: n/a | E8: n/a | F8: n/a | G8: n/a | H8: n/a | I8: n/a | J8: n/a | K8: n/a | L8: n/a | M8: n/a | N8: n/a | O8: n/a | P8: n/a | Q8: n/a | R8: n/a | S8: n/a | T8: n/a | U8: n/a | V8: n/a | W8: n/a | X8: n/a | Y8: n/a | Z8: n/a | AA8: n/a | AB8: n/a | AC8: n/a | AD8: n/a | AE8: n/a | AF8: n/a | AG8: n/a | AH8: n/a | AI8: n/a | AJ8: n/a | AK8: n/a | AL8: n/a | AM8: n/a | AN8: n/a | AO8: n/a | AP8: n/a | AQ8: n/a | AR8: n/a | AS8: n/a | AT8: n/a | AU8: n/a | AV8: n/a | AW8: n/a | AX8: n/a | AY8: n/a | AZ8: n/a | BA8: n/a | BB8: n/a | BC8: n/a | BD8: n/a | BE8: n/a | BF8: n/a | BG8: n/a
A9: S-CA-P12 | B9: =AVERAGE(densidade_hab_indL!B23:B25) -> 0.026666667 | C9: =AVERAGE(densidade_hab_indL!C23:C25) -> 0 | D9: =AVERAGE(densidade_hab_indL!D23:D25) -> 0 | E9: =AVERAGE(densidade_hab_indL!E23:E25) -> 0.44666667 | F9: =AVERAGE(densidade_hab_indL!F23:F25) -> 0 | G9: =AVERAGE(densidade_hab_indL!G23:G25) -> 0 | H9: =AVERAGE(densidade_hab_indL!H23:H25) -> 0 | I9: =AVERAGE(densidade_hab_indL!I23:I25) -> 0.066666667 | ... BG9: =AVERAGE(densidade_hab_indL!BG23:BG25) -> 0
A10: S-CA-P13 | B10: =AVERAGE(densidade_hab_indL!B26:B28) -> 0 | C10: =AVERAGE(densidade_hab_indL!C26:C28) -> 0 | D10: =AVERAGE(densidade_hab_indL!D26:D28) -> 0 | E10: =AVERAGE(densidade_hab_indL!E26:E28) -> 0.36666667 | F10: =AVERAGE(densidade_hab_indL!F26:F28) -> 0 | G10: =AVERAGE(densidade_hab_indL!G26:G28) -> 0 | H10: =AVERAGE(densidade_hab_indL!H26:H28) -> 0 | I10: =AVERAGE(densidade_hab_indL!I26:I28) -> 0 | ... BG10: =AVERAGE(densidade_hab_indL!BG26:BG28) -> 0
A11: S-CA-P14 | B11: =AVERAGE(densidade_hab_indL!B29:B31) -> 0 | C11: =AVERAGE(densidade_hab_indL!C29:C31) -> 0 | D11: =AVERAGE(densidade_hab_indL!D29:D31) -> 0 | E11: =AVERAGE(densidade_hab_indL!E29:E31) -> 0.6 | F11: =AVERAGE(densidade_hab_indL!F29:F31) -> 0 | G11: =AVERAGE(densidade_hab_indL!G29:G31) -> 0 | H11: =AVERAGE(densidade_hab_indL!H29:H31) -> 0 | I11: =AVERAGE(densidade_hab_indL!I29:I31) -> 0.013333333 | ... BG11: =AVERAGE(densidade_hab_indL!BG29:BG31) -> 0
A12: S-CA-P15 | B12: =AVERAGE(densidade_hab_indL!B32:B34) -> 0 | C12: =AVERAGE(densidade_hab_indL!C32:C34) -> 0 | D12: =AVERAGE(densidade_hab_indL!D32:D34) -> 0 | E12: =AVERAGE(densidade_hab_indL!E32:E34) -> 0.36666667 | F12: =AVERAGE(densidade_hab_indL!F32:F34) -> 0 | G12: =AVERAGE(densidade_hab_indL!G32:G34) -> 0 | H12: =AVERAGE(densidade_hab_indL!H32:H34) -> 0 | I12: =AVERAGE(densidade_hab_indL!I32:I34) -> 0.13333333 | ... BG12: =AVERAGE(densidade_hab_indL!BG32:BG34) -> 0
A13: S-CA-P16 | B13: =AVERAGE(densidade_hab_indL!B35:B37) -> 0.02 | C13: =AVERAGE(densidade_hab_indL!C35:C37) -> 0 | D13: =AVERAGE(densidade_hab_indL!D35:D37) -> 0.02 | E13: =AVERAGE(densidade_hab_indL!E35:E37) -> 0.52666667 | F13: =AVERAGE(densidade_hab_indL!F35:F37) -> 0 | G13: =AVERAGE(densidade_hab_indL!G35:G37) -> 0.026666667 | H13: =AVERAGE(densidade_hab_indL!H35:H37) -> 0 | I13: =AVERAGE(densidade_hab_indL!I35:I37) -> 1.1133333 | ... BG13: =AVERAGE(densidade_hab_indL!BG35:BG37) -> 0
A14: S-CA-P17 | B14: =AVERAGE(densidade_hab_indL!B38:B40) -> 0.02 | C14: =AVERAGE(densidade_hab_indL!C38:C40) -> 0 | D14: =AVERAGE(densidade_hab_indL!D38:D40) -> 0 | E14: =AVERAGE(densidade_hab_indL!E38:E40) -> 0.78 | F14: =AVERAGE(densidade_hab_indL!F38:F40) -> 0 | G14: =AVERAGE(densidade_hab_indL!G38:G40) -> 0 | H14: =AVERAGE(densidade_hab_indL!H38:H40) -> 0 | I14: =AVERAGE(densidade_hab_indL!I38:I40) -> 1.3133333 | ... BG14: =AVERAGE(densidade_hab_indL!BG38:BG40) -> 0
A15: S-CA-P18 | B15: =AVERAGE(densidade_hab_indL!B41:B43) -> 0.02 | C15: =AVERAGE(densidade_hab_indL!C41:C43) -> 0 | D15: =AVERAGE(densidade_hab_indL!D41:D43) -> 0 | E15: =AVERAGE(densidade_hab_indL!E41:E43) -> 0.31333333 | F15: =AVERAGE(densidade_hab_indL!F41:F43) -> 0 | G15: =AVERAGE(densidade_hab_indL!G41:G43) -> 0.02 | H15: =AVERAGE(densidade_hab_indL!H41:H43) -> 0 | I15: =AVERAGE(densidade_hab_indL!I41:I43) -> 0.15333333 | ... BG15: =AVERAGE(densidade_hab_indL!BG41:BG43) -> 0
A16: S-CA-P19 | B16: =AVERAGE(densidade_hab_indL!B44:B46) -> 0 | C16: =AVERAGE(densidade_hab_indL!C44:C46) -> 0.013333333 | D16: =AVERAGE(densidade_hab_indL!D44:D46) -> 0 | E16: =AVERAGE(densidade_hab_indL!E44:E46) -> 1.0133333 | F16: =AVERAGE(densidade_hab_indL!F44:F46) -> 0 | G16: =AVERAGE(densidade_hab_indL!G44:G46) -> 0.0066666667 | H16: =AVERAGE(densidade_hab_indL!H44:H46) -> 0 | I16: =AVERAGE(densidade_hab_indL!I44:I46) -> 0.02 | ... BG16: =AVERAGE(densidade_hab_indL!BG44:BG46) -> 0
A17: S-CA-P20 | B17: =AVERAGE(densidade_hab_indL!B47:B49) -> 0 | C17: =AVERAGE(densidade_hab_indL!C47:C49) -> 0.013333333 | D17: =AVERAGE(densidade_hab_indL!D47:D49) -> 0 | E17: =AVERAGE(densidade_hab_indL!E47:E49) -> 1.1533333 | F17: =AVERAGE(densidade_hab_indL!F47:F49) -> 0 | G17: =AVERAGE(densidade_hab_indL!G47:G49) -> 0 | H17: =AVERAGE(densidade_hab_indL!H47:H49) -> 0 | I17: =AVERAGE(densidade_hab_indL!I47:I49) -> 0.04 | ... BG17: =AVERAGE(densidade_hab_indL!BG47:BG49) -> 0
A18: C-BB-P05 | B18: =AVERAGE(densidade_hab_indL!B50:B52) -> 0.0066666667 | C18: =AVERAGE(densidade_hab_indL!C50:C52) -> 0 | D18: =AVERAGE(densidade_hab_indL!D50:D52) -> 0 | E18: =AVERAGE(densidade_hab_indL!E50:E52) -> 1.6666667 | F18: =AVERAGE(densidade_hab_indL!F50:F52) -> 0 | G18: =AVERAGE(densidade_hab_indL!G50:G52) -> 0 | H18: =AVERAGE(densidade_hab_indL!H50:H52) -> 0 | I18: =AVERAGE(densidade_hab_indL!I50:I52) -> 0.54666667 | ... BG18: =AVERAGE(densidade_hab_indL!BG50:BG52) -> 0
A19: C-BB-P06 | B19: =AVERAGE(densidade_hab_indL!B53:B55) -> 0.026666667 | C19: =AVERAGE(densidade_hab_indL!C53:C55) -> 0 | D19: =AVERAGE(densidade_hab_indL!D53:D55) -> 0 | E19: =AVERAGE(densidade_hab_indL!E53:E55) -> 1.3266667 | F19: =AVERAGE(densidade_hab_indL!F53:F55) -> 0 | G19: =AVERAGE(densidade_hab_indL!G53:G55) -> 0 | H19: =AVERAGE(densidade_hab_indL!H53:H55) -> 0 | I19: =AVERAGE(densidade_hab_indL!I53:I55) -> 0.06 | ... BG19: =AVERAGE(densidade_hab_indL!BG53:BG55) -> 0
A20: C-BB-P07 | B20: =AVERAGE(densidade_hab_indL!B56:B58) -> 0.013333333 | C20: =AVERAGE(densidade_hab_indL!C56:C58) -> 0 | D20: =AVERAGE(densidade_hab_indL!D56:D58) -> 0 | E20: =AVERAGE(densidade_hab_indL!E56:E58) -> 1.5266667 | F20: =AVERAGE(densidade_hab_indL!F56:F58) -> 0 | G20: =AVERAGE(densidade_hab_indL!G56:G58) -> 0 | H20: =AVERAGE(densidade_hab_indL!H56:H58) -> 0 | I20: =AVERAGE(densidade_hab_indL!I56:I58) -> 0.093333333 | ... BG20: =AVERAGE(densidade_hab_indL!BG56:BG58) -> 0
A21: C-BB-P08 | B21: =AVERAGE(densidade_hab_indL!B59:B61) -> 5.2866667 | C21: =AVERAGE(densidade_hab_indL!C59:C61) -> 1.0533333 | D21: =AVERAGE(densidade_hab_indL!D59:D61) -> 0.38 | E21: =AVERAGE(densidade_hab_indL!E59:E61) -> 3.4 | F21: =AVERAGE(densidade_hab_indL!F59:F61) -> 0.0066666667 | G21: =AVERAGE(densidade_hab_indL!G59:G61) -> 0 | H21: =AVERAGE(densidade_hab_indL!H59:H61) -> 0 | I21: =AVERAGE(densidade_hab_indL!I59:I61) -> 12.146667 | ... BG21: =AVERAGE(densidade_hab_indL!BG59:BG61) -> 0
A22: C-BB-P09 | B22: =AVERAGE(densidade_hab_indL!B62:B64) -> 0.013333333 | C22: =AVERAGE(densidade_hab_indL!C62:C64) -> 0.013333333 | D22: =AVERAGE(densidade_hab_indL!D62:D64) -> 0 | E22: =AVERAGE(densidade_hab_indL!E62:E64) -> 2.0066667 | F22: =AVERAGE(densidade_hab_indL!F62:F64) -> 0 | G22: =AVERAGE(densidade_hab_indL!G62:G64) -> 0 | H22: =AVERAGE(densidade_hab_indL!H62:H64) -> 0 | I22: =AVERAGE(densidade_hab_indL!I62:I64) -> 0 | ... BG22: =AVERAGE(densidade_hab_indL!BG62:BG64) -> 0
A23: C-BB-P10 | B23: =AVERAGE(densidade_hab_indL!B65:B67) -> 0.36 | C23: =AVERAGE(densidade_hab_indL!C65:C67) -> 0.06 | D23: =AVERAGE(densidade_hab_indL!D65:D67) -> 0.046666667 | E23: =AVERAGE(densidade_hab_indL!E65:E67) -> 2.94 | F23: =AVERAGE(densidade_hab_indL!F65:F67) -> 0.013333333 | G23: =AVERAGE(densidade_hab_indL!G65:G67) -> 0.053333333 | H23: =AVERAGE(densidade_hab_indL!H65:H67) -> 0 | I23: =AVERAGE(densidade_hab_indL!I65:I67) -> 0.53333333 | ... BG23: =AVERAGE(densidade_hab_indL!BG65:BG67) -> 0
A24: C-CA-P11 | B24: n/a | C24: n/a | D24: n/a | E24: n/a | F24: n/a | G24: n/a | H24: n/a | I24: n/a | J24: n/a | K24: n/a | L24: n/a | M24: n/a | N24: n/a | O24: n/a | P24: n/a | Q24: n/a | R24: n/a | S24: n/a | T24: n/a | U24: n/a | V24: n/a | W24: n/a | X24: n/a | Y24: n/a | Z24: n/a | AA24: n/a | AB24: n/a | AC24: n/a | AD24: n/a | AE24: n/a | AF24: n/a | AG24: n/a | AH24: n/a | AI24: n/a | AJ24: n/a | AK24: n/a | AL24: n/a | AM24: n/a | AN24: n/a | AO24: n/a | AP24: n/a | AQ24: n/a | AR24: n/a | AS24: n/a | AT24: n/a | AU24: n/a | AV24: n/a | AW24: n/a | AX24: n/a | AY24: n/a | AZ24: n/a | BA24: n/a | BB24: n/a | BC24: n/a | BD24: n/a | BE24: n/a | BF24: n/a | BG24: n/a
A25: C-CA-P12 | B25: =AVERAGE(densidade_hab_indL!B71:B73) -> 0.066666667 | C25: =AVERAGE(densidade_hab_indL!C71:C73) -> 0 | D25: =AVERAGE(densidade_hab_indL!D71:D73) -> 0 | E25: =AVERAGE(densidade_hab_indL!E71:E73) -> 3.32 | F25: =AVERAGE(densidade_hab_indL!F71:F73) -> 0 | G25: =AVERAGE(densidade_hab_indL!G71:G73) -> 0 | H25: =AVERAGE(densidade_hab_indL!H71:H73) -> 0 | I25: =AVERAGE(densidade_hab_indL!I71:I73) -> 0.11333333 | ... BG25: =AVERAGE(densidade_hab_indL!BG71:BG73) -> 0
A26: C-CA-P13 | B26: =AVERAGE(densidade_hab_indL!B74:B76) -> 0.08 | C26: =AVERAGE(densidade_hab_indL!C74:C76) -> 0.013333333 | D26: =AVERAGE(densidade_hab_indL!D74:D76) -> 0 | E26: =AVERAGE(densidade_hab_indL!E74:E76) -> 2.46 | F26: =AVERAGE(densidade_hab_indL!F74:F76) -> 0.0066666667 | G26: =AVERAGE(densidade_hab_indL!G74:G76) -> 0 | H26: =AVERAGE(densidade_hab_indL!H74:H76) -> 0 | I26: =AVERAGE(densidade_hab_indL!I74:I76) -> 0.25333333 | ... BG26: =AVERAGE(densidade_hab_indL!BG74:BG76) -> 0
A27: C-CA-P14 | B27: =AVERAGE(densidade_hab_indL!B77:B79) -> 0.066666667 | C27: =AVERAGE(densidade_hab_indL!C77:C79) -> 0.0066666667 | D27: =AVERAGE(densidade_hab_indL!D77:D79) -> 0 | E27: =AVERAGE(densidade_hab_indL!E77:E79) -> 1.7466667 | F27: =AVERAGE(densidade_hab_indL!F77:F79) -> 0.0066666667 | G27: =AVERAGE(densidade_hab_indL!G77:G79) -> 0 | H27: =AVERAGE(densidade_hab_indL!H77:H79) -> 0 | I27: =AVERAGE(densidade_hab_indL!I77:I79) -> 0.1 | ... BG27: =AVERAGE(densidade_hab_indL!BG77:BG79) -> 0
A28: C-CA-P15 | B28: =AVERAGE(densidade_hab_indL!B80:B82) -> 0.026666667 | C28: =AVERAGE(densidade_hab_indL!C80:C82) -> 0 | D28: =AVERAGE(densidade_hab_indL!D80:D82) -> 0 | E28: =AVERAGE(densidade_hab_indL!E80:E82) -> 1.8733333 | F28: =AVERAGE(densidade_hab_indL!F80:F82) -> 0.04 | G28: =AVERAGE(densidade_hab_indL!G80:G82) -> 0 | H28: =AVERAGE(densidade_hab_indL!H80:H82) -> 0 | I28: =AVERAGE(densidade_hab_indL!I80:I82) -> 0.04 | ... BG28: =AVERAGE(densidade_hab_indL!BG80:BG82) -> 0
A29: C-CA-P16 | B29: =AVERAGE(densidade_hab_indL!B83:B85) -> 0.63333333 | C29: =AVERAGE(densidade_hab_indL!C83:C85) -> 0.22 | D29: =AVERAGE(densidade_hab_indL!D83:D85) -> 0.20666667 | E29: =AVERAGE(densidade_hab_indL!E83:E85) -> 1.8733333 | F29: =AVERAGE(densidade_hab_indL!F83:F85) -> 1.24 | G29: =AVERAGE(densidade_hab_indL!G83:G85) -> 0 | H29: =AVERAGE(densidade_hab_indL!H83:H85) -> 0.053333333 | I29: =AVERAGE(densidade_hab_indL!I83:I85) -> 7.8733333 | ... BG29: =AVERAGE(densidade_hab_indL!BG83:BG85) -> 0
A30: C-CA-P17 | B30: =AVERAGE(densidade_hab_indL!B86:B88) -> 0.12666667 | C30: =AVERAGE(densidade_hab_indL!C86:C88) -> 0 | D30: =AVERAGE(densidade_hab_indL!D86:D88) -> 0.02 | E30: =AVERAGE(densidade_hab_indL!E86:E88) -> 1.54 | F30: =AVERAGE(densidade_hab_indL!F86:F88) -> 0.13333333 | G30: =AVERAGE(densidade_hab_indL!G86:G88) -> 0 | H30: =AVERAGE(densidade_hab_indL!H86:H88) -> 0 | I30: =AVERAGE(densidade_hab_indL!I86:I88) -> 0.37333333 | ... BG30: =AVERAGE(densidade_hab_indL!BG86:BG88) -> 0
A31: C-CA-P18 | B31: =AVERAGE(densidade_hab_indL!B89:B91) -> 0.11333333 | C31: =AVERAGE(densidade_hab_indL!C89:C91) -> 0.0066666667 | D31: =AVERAGE(densidade_hab_indL!D89:D91) -> 0 | E31: =AVERAGE(densidade_hab_indL!E89:E91) -> 1.4066667 | F31: =AVERAGE(densidade_hab_indL!F89:F91) -> 0.046666667 | G31: =AVERAGE(densidade_hab_indL!G89:G91) -> 0 | H31: =AVERAGE(densidade_hab_indL!H89:H91) -> 0 | I31: =AVERAGE(densidade_hab_indL!I89:I91) -> 0.92666667 | ... BG31: =AVERAGE(densidade_hab_indL!BG89:BG91) -> 0
A32: C-CA-P19 | B32: =AVERAGE(densidade_hab_indL!B92:B94) -> 0.0066666667 | C32: =AVERAGE(densidade_hab_indL!C92:C94) -> 0.066666667 | D32: =AVERAGE(densidade_hab_indL!D92:D94) -> 0 | E32: =AVERAGE(densidade_hab_indL!E92:E94) -> 1.1866667 | F32: =AVERAGE(densidade_hab_indL!F92:F94) -> 0 | G32: =AVERAGE(densidade_hab_indL!G92:G94) -> 0 | H32: =AVERAGE(densidade_hab_indL!H92:H94) -> 0 | I32: =AVERAGE(densidade_hab_indL!I92:I94) -> 0.033333333 | ... BG32: =AVERAGE(densidade_hab_indL!BG92:BG94) -> 0
A33: C-CA-P20 | B33: =AVERAGE(densidade_hab_indL!B95:B97) -> 0.0066666667 | C33: =AVERAGE(densidade_hab_indL!C95:C97) -> 0.0066666667 | D33: =AVERAGE(densidade_hab_indL!D95:D97) -> 0 | E33: =AVERAGE(densidade_hab_indL!E95:E97) -> 0.82666667 | F33: =AVERAGE(densidade_hab_indL!F95:F97) -> 0 | G33: =AVERAGE(densidade_hab_indL!G95:G97) -> 0 | H33: =AVERAGE(densidade_hab_indL!H95:H97) -> 0 | I33: =AVERAGE(densidade_hab_indL!I95:I97) -> 0.013333333 | ... BG33: =AVERAGE(densidade_hab_indL!BG95:BG97) -> 0

Sheet codes
A1: P01C1-H1-I | D1: Amostra (50L/80mL) | E1: Alíquota (1mL)
A2: Ponto | B2: Coleta | C2: Datas | D2: Habitat=Pote | E2: Lâmina
A3: P01 | B3: C1 | C3: x | D3: -H1 | E3: -I
A4: P02 | B4: x | C4: x | D4: -H2 | E4: -II
A5: P03 | B5: x | C5: x | D5: -H3 | E5: -III
A6: P04 | B6: x | C6: x | D6: x | E6: x
A7: P05 | B7: x | C7: x | D7: x | E7: x
A8: 40 | B8: x | C8: x | D8: 3 | E8: 3
A9: =A8*1 -> 40 | B9: x | C9: x | D9: =D8*A8 -> 120 | E9: =E8*D9 -> 360
A13: Em vermelho | B13: conferir ou alterado
A14: Em azul | B14: errado
A15: Em verde | B15: não foram nós que identificamos
A16: Em rosa | B16: corrigir
A17: Em preto | B17: conferido por Elvio

Sheet Espécies
A1: TOTAL REBIO 2012 | J1: TOTAL REBIO 2023 | Q1: Lista de acordo com:
A2: ="total = "&SUM(B3:B121) -> total = 84 | C2: ROTIFERA | J2: ="total = "&SUM(K3:K91) -> total = 58 | L2: ROTIFERA | Q2: https://www.gbif.org/
A3: ="Rotifera = "&SUM(B3:B88) -> Rotifera = 63 | C3: DIGONONTA | E3: Barro Branco | F3: Caiana | G3: Entorno | H3: REBio | J3: ="Rotifera = "&SUM(K3:K59) -> Rotifera = 40 | L3: DIGONONTA | N3: ="N= "&SUM(N4:N131) -> N= 4420 | Q3: https://www.nies.go.jp/chiiki1/protoz/index.html
A4: ="Rot spp = "&SUM(B6:B88) -> Rot spp = 62 | B4: 1 | C4: BDELLOIDEA | D4: Bdelloidea | E4: 1.7432099 | F4: 1.6197531 | G4: 0 | H4: 0 | J4: ="Cladocera = "&SUM(K61:K79) -> Cladocera = 12 | K4: 1 | L4: Bdelloidea | M4: Bdelloidea | N4: =SUM(rebio23_80ml!E3:E50) -> 1829 | Q4: https://www.nies.go.jp/chiiki1/protoz/identi-r.htm
A5: ="Cladocera = "&SUM(B94:B112) -> Cladocera = 15 | B5: 0 | C5: Philodinidae | J5: ="Copepoda = "&SUM(K81:K91) -> Copepoda = 6 | K5: 0 | L5: Philodinidae
A6: ="Copepoda = "&SUM(B114:B122) -> Copepoda = 6 | B6: 1 | C6: Dissotrocha aculeata (Ehrenberg, 1832) | D6: Dis.aculeata | E6: 0 | F6: 0 | G6: 0.48 | H6: 0.35555556 | J6: ="Rot spp = "&SUM(K5:K59) -> Rot spp = 39 | K6: 1 | L6: Dissotrocha aculeata (Ehrenberg, 1832) | M6: Dis.aculeata | N6: =SUM(rebio23_80ml!N3:N50) -> 2
A7: ="Rot fam = "&COUNTIF(B4:B88,"0") -> Rot fam = 19 | B7: 1 | C7: Rotaria neptunia (Ehrenberg, 1830) | D7: Rot.neptunia | E7: 0 | F7: 0 | G7: 0.16 | H7: 0 | J7: ="Rot fam = "&COUNTIF(K4:K59,"0") -> Rot fam = 14 | K7: 0 | L7: Dicranophoridae
A8: ="Phil = "&SUM(B6:B8) -> Phil = 3 | B8: 1 | C8: Rotaria sp. | D8: Rotaria.sp | E8: 0.16790123 | F8: 0.31604938 | G8: 3.52 | H8: 10.133333 | J8: ="Phil = "&SUM(K6) -> Phil = 1 | K8: 1 | L8: Dicranophoroides sp. | M8: Dicranop.sp | N8: =SUM(rebio23_80ml!K3:K50) -> 2
A9: ="Dicran = "&SUM(B12) -> Dicran = 1 | C9: MONOGONONTA | J9: ="Dicran = "&SUM(K8) -> Dicran = 1 | K9: 0 | L9: Notommatidae
A10: ="Lec = "&SUM(B14:B31) -> Lec = 18 | C10: PLOIMA | J10: ="Lec = "&SUM(K13:K28) -> Lec = 15 | K10: 1 | L10: Cephalodella sp. | M10: Cephalodella.sp | N10: =SUM(rebio23_80ml!G3:G50) -> 10
A11: ="Bra = "&SUM(B33:B46) -> Bra = 14 | B11: 0 | C11: Dicranophoridae | J11: ="Bra = "&SUM(K30:K32) -> Bra = 3 | L11: MONOGONONTA
A12: ="Lep = "&SUM(B48:B51) -> Lep = 4 | B12: 1 | C12: Dicranophoroides sp. | D12: Dicranop.sp | E12: 0 | F12: 0 | G12: 6.88 | H12: 0 | J12: ="Lep = "&SUM(K34:K37) -> Lep = 4 | L12: FLOSCULARIACEA
A13: ="Chy = "&SUM(B94:B100) -> Chy = 7 | B13: 0 | C13: Lecanidae | J13: ="Chy = "&SUM(K63:K68) -> Chy = 5 | K13: 0 | L13: Lecanidae
A14: ="Mac = "&SUM(B102:B105) -> Mac = 4 | B14: 1 | C14: Lecane aculeata (Jakubski, 1912) | D14: Lec.aculeata | E14: 0.14814815 | F14: 0.069135802 | G14: 0 | H14: 0 | J14: ="Mac = "&SUM(K69:K72) -> Mac = 3 | K14: 1 | L14: Lecane aculeata (Jakubski, 1912) | M14: Lec.aculeata | N14: =SUM(rebio23_80ml!R3:R50) -> 1
A15: ="Sid = "&SUM(B107:B108) -> Sid = 2 | B15: 1 | C15: Lecane bulla (Gosse, 1851) | D15: Lec.bulla | E15: 0.78024691 | F15: 0.99753086 | G15: 8.96 | H15: 1.0666667 | J15: ="Sid = "&SUM(K74:K75) -> Sid = 2 | K15: 1 | L15: Lecane bulla (Gosse, 1851) | M15: Lec.bulla | N15: =SUM(rebio23_80ml!S3:S50) -> 80
A16: ="Juv = "&SUM(B114:B115) -> Juv = 2 | B16: 1 | C16: Lecane cornuta (Müller, 1786) | D16: Lec.cornuta | E16: 0.02962963 | F16: 0.049382716 | G16: 0.42666667 | H16: 0 | J16: ="Juv = "&SUM(K81:K82) -> Juv = 2 | K16: 1 | L16: Lecane cornuta (Müller, 1786) | M16: Lec.cornuta | N16: =SUM(rebio23_80ml!T3:T50) -> 9
A17: ="Cyc = "&SUM(B118:B119) -> Cyc = 1 | B17: 1 | C17: Lecane crepida Harring, 1914 | D17: Lec.crepida | E17: 0.0098765432 | F17: 0.049382716 | G17: 0.053333333 | H17: 0 | J17: ="Cyc = "&SUM(K84:K87) -> Cyc = 3 | K17: 1 | L17: Lecane crepida Harring, 1914 | M17: Lec.crepida | N17: =SUM(rebio23_80ml!U3:U50) -> 15
A18: ="Dia = "&SUM(B120:B121) -> Dia = 1 | B18: 1 | C18: Lecane curvicornis (Murray, 1913) | D18: Lec.curvicornis | E18: 0.0098765432 | F18: 0 | G18: 0.32 | H18: 0 | J18: ="Dia = "&SUM(K89:K90) -> Dia = 1 | K18: 1 | L18: Lecane curvicornis (Murray, 1913) | M18: Lec.curvicornis | N18: =SUM(rebio23_80ml!V3:V50) -> 7
B19: 1 | C19: Lecane elasma Harring & Myers, 1926 | D19: Lec.elasma | E19: 0 | F19: 0.0098765432 | G19: 0 | H19: 0 | K19: 1 | L19: Lecane furcata (Murray, 1913) | M19: Lec.furcata | N19: =SUM(rebio23_80ml!W3:W50) -> 1
B20: 1 | C20: Lecane furcata (Murray, 1913) | D20: Lec.furcata | E20: 0 | F20: 0.069135802 | G20: 1.2266667 | H20: 0.17777778 | K20: 1 | L20: Lecane leontina (Turner, 1892) | M20: Lec.leontina | N20: =SUM(rebio23_80ml!Y3:Y50) -> 10
B21: 1 | C21: Lecane hastata (Murray, 1913) | D21: Lec.hastata | E21: 0 | F21: 0.0098765432 | G21: 0.16 | H21: 0 | K21: 1 | L21: Lecane lunaris (Ehrenberg, 1832) | M21: Lec.lunaris | N21: =SUM(rebio23_80ml!Z3:Z50) -> 11
B22: 1 | C22: Lecane hornemanni (Ehrenberg, 1834) | D22: Lec.hornemanni | E22: 0 | F22: 0 | G22: 0.37333333 | H22: 0 | K22: 1 | L22: Lecane luna (Müller, 1776) | M22: Lec.luna | N22: =SUM(rebio23_80ml!AA3:AA50) -> 21
B23: 1 | C23: Lecane kluchor Tarnogradski, 1930 | D23: Lec.kluchor | E23: 0.0098765432 | F23: 0.059259259 | G23: 0 | H23: 0 | K23: 1 | L23: Lecane monostyla (Daday, 1897): | M23: Lec.monostyla | N23: =SUM(rebio23_80ml!AB3:AB50) -> 2
B24: 1 | C24: Lecane leontina (Turner, 1892) | D24: Lec.leontina | E24: 0.019753086 | F24: 0.049382716 | G24: 0.26666667 | H24: 0 | K24: 1 | L24: Lecane papuana (Murray, 1913) | M24: Lec.papuana | N24: =SUM(rebio23_80ml!AD3:AD50) -> 5
B25: 1 | C25: Lecane ligona (Dunlop, 1901) | D25: Lec.ligona | E25: 0 | F25: 0.088888889 | G25: 0 | H25: 0 | K25: 1 | L25: Lecane quadridentata (Ehrenberg, 1830) | M25: Lec.quadridentata | N25: =SUM(rebio23_80ml!AE3:AE50) -> 2
B26: 1 | C26: Lecane lunaris (Ehrenberg, 1832) | D26: Lec.lunaris | E26: 0.14814815 | F26: 0.10864198 | G26: 0.32 | H26: 0.88888889 | K26: 1 | L26: Lecane sp.1 | M26: Lecane.sp1 | N26: =SUM(rebio23_80ml!X3:X50) -> 2
B27: 1 | C27: Lecane luna (Müller, 1776) | D27: Lec.luna | E27: 0 | F27: 0 | G27: 0.26666667 | H27: 0 | K27: 1 | L27: Lecane sp.2 | M27: Lecane.sp2 | N27: =SUM(rebio23_80ml!AC3:AC50) -> 3
B28: 1 | C28: Lecane monostyla (Daday, 1897): | D28: Lec.monostyla | E28: 0 | F28: 0.039506173 | G28: 0.10666667 | H28: 0 | K28: 1 | L28: Lecane sp.3 | M28: Lecane.sp3 | N28: =SUM(rebio23_80ml!AF3:AF50) -> 1
B29: 1 | C29: Lecane ovalis (Jakubski, 1914) | D29: Lec.ovalis | E29: 0.019753086 | F29: 0.0098765432 | G29: 0 | H29: 0 | K29: 0 | L29: Brachionidae
B30: 1 | C30: Lecane quadridentata (Ehrenberg, 1830) | D30: Lec.quadridentata | E30: 0.0098765432 | F30: 0.049382716 | G30: 0 | H30: 0.17777778 | K30: 1 | L30: Brachionus patulus Müller, 1786 | M30: Bra.patulus | N30: =SUM(rebio23_80ml!F3:F50) -> 3
B31: 1 | C31: Lecane sp. | D31: Lecane.sp | E31: 0.0098765432 | F31: 0.02962963 | G31: 0 | H31: 0 | K31: 1 | L31: Macrochaetus sp. | M31: Macrochaetus.sp | N31: =SUM(rebio23_80ml!AN3:AN50) -> 4
B32: 0 | C32: Brachionidae | K32: 1 | L32: Platyias quadricornis (Ehrenberg, 1832) | M32: Pla.quadricornis | N32: =SUM(rebio23_80ml!AY3:AY50) -> 8
B33: 1 | C33: Brachionus urceolaris Müller, 1773 | D33: Bra.urceolaris | E33: 0.0098765432 | F33: 0.019753086 | G33: 0 | H33: 0 | K33: 0 | L33: Lepadellidae
B34: 1 | C34: Brachionus calyciflorus Pallas, 1766 | D34: Bra.calyciflorus | E34: 0 | F34: 0.0098765432 | G34: 0 | H34: 0 | K34: 1 | L34: Lepadella ovalis (Müller, 1786) | M34: Lep.ovalis | N34: =SUM(rebio23_80ml!AJ3:AJ50) -> 20
B35: 1 | C35: Brachionus caudatus Barrois & Daday, 1894 | D35: Bra.caudatus | E35: 0 | F35: 0.019753086 | G35: 0 | H35: 0 | K35: 1 | L35: Lepadella patella (Müller, 1773) | M35: Lep.patella | N35: =SUM(rebio23_80ml!AK3:AK50) -> 2
B36: 1 | C36: Brachionus angularis Gosse, 1851 | D36: Bra.angularis | E36: 0.059259259 | F36: 0.039506173 | G36: 0 | H36: 0 | K36: 1 | L36: Lepadella imbricata Harring, 1914 | M36: Lep.imbricata | N36: =SUM(rebio23_80ml!AH3:AH49) -> 1
B37: 1 | C37: Brachionus havanaensis Rousselet, 1911 | D37: Bra.havanaensis | E37: 0 | F37: 0.0098765432 | G37: 0 | H37: 0 | K37: 1 | L37: Lepadella sp. | M37: Lepadella.sp | N37: =SUM(rebio23_80ml!AI3:AI50) -> 1
B38: 1 | C38: Brachionus falcatus Zacharias, 1898 | D38: Bra.falcatus | E38: 0 | F38: 0.0098765432 | G38: 2.4 | H38: 0.53333333 | K38: 0 | L38: Euchlanidae
B39: 1 | C39: Brachionus quadridentatus Hermann, 1783 | D39: Bra.quadridentatus | E39: 0 | F39: 0 | G39: 1.0133333 | H39: 0 | K39: 1 | L39: Euchlanis dilatata Ehrenberg, 1832 | M39: Euc.dilatata | N39: =SUM(rebio23_80ml!O3:O50) -> 1
B40: 1 | C40: Platyias quadricornis (Ehrenberg, 1832) | D40: Pla.quadricornis | E40: 0 | F40: 0.0098765432 | G40: 0.053333333 | H40: 0 | K40: 0 | L40: Synchaetidae
...

Sheet escalas_final
B1: partição total | E1: seco | J1: chuvoso | O1: barro branco | S1: caiana
A2: ="n = "&COUNTA(A3:A1014) -> n = 96 | B2: pt.rio | C2: pt.periodo | D2: pt.rebio | E2: s.habitat | F2: s.ponto | G2: s.trecho | H2: s.rio | I2: s.rebio | J2: c.habitat | K2: c.ponto | L2: c.trecho | M2: c.rio | N2: c.rebio | O2: bb.habitat | P2: bb.ponto | Q2: bb.trecho | R2: bb.rio | S2: ca.habitat | T2: ca.ponto | U2: ca.trecho | V2: ca.rio
A3: =rebio23_80ml!A3 -> S-B-P05-H1 | B3: 111 | C3: 11 | D3: 1 | E3: 11111 | F3: 1111 | G3: 111 | H3: 11 | I3: 1 | O3: 1111 | P3: 111 | Q3: 11 | R3: 1
A4: =rebio23_80ml!A4 -> S-B-P05-H2 | B4: 111 | C4: 11 | D4: 1 | E4: 11112 | F4: 1111 | G4: 111 | H4: 11 | I4: 1 | O4: 1112 | P4: 111 | Q4: 11 | R4: 1
A5: =rebio23_80ml!A5 -> S-B-P05-H3 | B5: 111 | C5: 11 | D5: 1 | E5: 11113 | F5: 1111 | G5: 111 | H5: 11 | I5: 1 | O5: 1113 | P5: 111 | Q5: 11 | R5: 1
A6: =rebio23_80ml!A6 -> S-B-P06-H1 | B6: 111 | C6: 11 | D6: 1 | E6: 11114 | F6: 1112 | G6: 111 | H6: 11 | I6: 1 | O6: 1114 | P6: 112 | Q6: 11 | R6: 1
A7: =rebio23_80ml!A7 -> S-B-P06-H2 | B7: 111 | C7: 11 | D7: 1 | E7: 11115 | F7: 1112 | G7: 111 | H7: 11 | I7: 1 | O7: 1115 | P7: 112 | Q7: 11 | R7: 1
A8: =rebio23_80ml!A8 -> S-B-P06-H3 | B8: 111 | C8: 11 | D8: 1 | E8: 11116 | F8: 1112 | G8: 111 | H8: 11 | I8: 1 | O8: 1116 | P8: 112 | Q8: 11 | R8: 1
A9: =rebio23_80ml!A9 -> S-B-P07-H1 | B9: 111 | C9: 11 | D9: 1 | E9: 11117 | F9: 1113 | G9: 111 | H9: 11 | I9: 1 | O9: 1117 | P9: 113 | Q9: 11 | R9: 1
A10: =rebio23_80ml!A10 -> S-B-P07-H2 | B10: 111 | C10: 11 | D10: 1 | E10: 11118 | F10: 1113 | G10: 111 | H10: 11 | I10: 1 | O10: 1118 | P10: 113 | Q10: 11 | R10: 1
A11: =rebio23_80ml!A11 -> S-B-P07-H3 | B11: 111 | C11: 11 | D11: 1 | E11: 11119 | F11: 1113 | G11: 111 | H11: 11 | I11: 1 | O11: 1119 | P11: 113 | Q11: 11 | R11: 1
A12: =rebio23_80ml!A12 -> S-B-P08-H1 | B12: 111 | C12: 11 | D12: 1 | E12: 11120 | F12: 1114 | G12: 112 | H12: 11 | I12: 1 | O12: 1120 | P12: 114 | Q12: 12 | R12: 1
A13: =rebio23_80ml!A13 -> S-B-P08-H2 | B13: 111 | C13: 11 | D13: 1 | E13: 11121 | F13: 1114 | G13: 112 | H13: 11 | I13: 1 | O13: 1121 | P13: 114 | Q13: 12 | R13: 1
A14: =rebio23_80ml!A14 -> S-B-P08-H3 | B14: 111 | C14: 11 | D14: 1 | E14: 11122 | F14: 1114 | G14: 112 | H14: 11 | I14: 1 | O14: 1122 | P14: 114 | Q14: 12 | R14: 1
... A20: =rebio23_80ml!A20 -> S-B-P10-H3 | B20: 111 | C20: 11 | D20: 1 | E20: 11128 | F20: 1116 | G20: 112 | H20: 11 | I20: 1 | O20: 1128 | P20: 116 | Q20: 12 | R20: 1
A21: =rebio23_80ml!A21 -> S-C-P11-H1
A22: =rebio23_80ml!A22 -> S-C-P11-H2
A23: =rebio23_80ml!A23 -> S-C-P11-H3
A24: =rebio23_80ml!A24 -> S-C-P12-H1 | B24: 112 | C24: 11 | D24: 1 | E24: 11129 | F24: 1117 | G24: 113 | H24: 12 | I24: 1 | S24: 1111 | T24: 111 | U24: 11 | V24: 1
A25: =rebio23_80ml!A25 -> S-C-P12-H2 | B25: 112 | C25: 11 | D25: 1 | E25: 11130 | F25: 1117 | G25: 113 | H25: 12 | I25: 1 | S25: 1112 | T25: 111 | U25: 11 | V25: 1
A26: =rebio23_80ml!A26 -> S-C-P12-H3 | B26: 112 | C26: 11 | D26: 1 | E26: 11131 | F26: 1117 | G26: 113 | H26: 12 | I26: 1 | S26: 1113 | T26: 111 | U26: 11 | V26: 1
A27: =rebio23_80ml!A27 -> S-C-P13-H1 | B27: 112 | C27: 11 | D27: 1 | E27: 11132 | F27: 1118 | G27: 113 | H27: 12 | I27: 1 | S27: 1114 | T27: 112 | U27: 11 | V27: 1
A28: =rebio23_80ml!A28 -> S-C-P13-H2 | B28: 112 | C28: 11 | D28: 1 | E28: 11133 | F28: 1118 | G28: 113 | H28: 12 | I28: 1 | S28: 1115 | T28: 112 | U28: 11 | V28: 1
A29: =rebio23_80ml!A29 -> S-C-P13-H3 | B29: 112 | C29: 11 | D29: 1 | E29: 11134 | F29: 1118 | G29: 113 | H29: 12 | I29: 1 | S29: 1116 | T29: 112 | U29: 11 | V29: 1
A30: =rebio23_80ml!A30 -> S-C-P14-H1 | B30: 112 | C30: 11 | D30: 1 | E30: 11135 | F30: 1119 | G30: 113 | H30: 12 | I30: 1 | S30: 1117 | T30: 113 | U30: 11 | V30: 1
A31: =rebio23_80ml!A31 -> S-C-P14-H2 | B31: 112 | C31: 11 | D31: 1 | E31: 11136 | F31: 1119 | G31: 113 | H31: 12 | I31: 1 | S31: 1118 | T31: 113 | U31: 11 | V31: 1
A32: =rebio23_80ml!A32 -> S-C-P14-H3 | B32: 112 | C32: 11 | D32: 1 | E32: 11137 | F32: 1119 | G32: 113 | H32: 12 | I32: 1 | S32: 1119 | T32: 113 | U32: 11 | V32: 1
A33: =rebio23_80ml!A33 -> S-C-P15-H1 | B33: 112 | C33: 11 | D33: 1 | E33: 11138 | F33: 1120 | G33: 113 | H33: 12 | I33: 1 | S33: 1120 | T33: 114 | U33: 11 | V33: 1
A34: =rebio23_80ml!A34 -> S-C-P15-H2 | B34: 112 | C34: 11 | D34: 1 | E34: 11139 | F34: 1120 | G34: 113 | H34: 12 | I34: 1 | S34: 1121 | T34: 114 | U34: 11 | V34: 1
A35: =rebio23_80ml!A35 -> S-C-P15-H3 | B35: 112 | C35: 11 | D35: 1 | E35: 11140 | F35: 1120 | G35: 113 | H35: 12 | I35: 1 | S35: 1122 | T35: 114 | U35: 11 | V35: 1
... A50: =rebio23_80ml!A50 -> S-C-P20-H3 | B50: 112 | C50: 11 | D50: 1 | E50: 11155 | F50: 1125 | G50: 114 | H50: 12 | I50: 1 | S50: 1137 | T50: 119 | U50: 12 | V50: 1
A51: =rebio23_80ml!A51 -> C-B-P05-H1 | B51: 113 | C51: 12 | D51: 1 | J51: 11111 | K51: 1111 | L51: 111 | M51: 11 | N51: 1 | O51: 1111 | P51: 111 | Q51: 11 | R51: 1
A52: =rebio23_80ml!A52 -> C-B-P05-H2 | B52: 113 | C52: 12 | D52: 1 | J52: 11112 | K52: 1111 | L52: 111 | M52: 11 | N52: 1 | O52: 1112 | P52: 111 | Q52: 11 | R52: 1
A53: =rebio23_80ml!A53 -> C-B-P05-H3 | B53: 113 | C53: 12 | D53: 1 | J53: 11113 | K53: 1111 | L53: 111 | M53: 11 | N53: 1 | O53: 1113 | P53: 111 | Q53: 11 | R53: 1
A54: =rebio23_80ml!A54 -> C-B-P06-H1 | B54: 113 | C54: 12 | D54: 1 | J54: 11114 | K54: 1112 | L54: 111 | M54: 11 | N54: 1 | O54: 1114 | P54: 112 | Q54: 11 | R54: 1
A55: =rebio23_80ml!A55 -> C-B-P06-H2 | B55: 113 | C55: 12 | D55: 1 | J55: 11115 | K55: 1112 | L55: 111 | M55: 11 | N55: 1 | O55: 1115 | P55: 112 | Q55: 11 | R55: 1
A56: =rebio23_80ml!A56 -> C-B-P06-H3 | B56: 113 | C56: 12 | D56: 1 | J56: 11116 | K56: 1112 | L56: 111 | M56: 11 | N56: 1 | O56: 1116 | P56: 112 | Q56: 11 | R56: 1
A57: =rebio23_80ml!A57 -> C-B-P07-H1 | B57: 113 | C57: 12 | D57: 1 | J57: 11117 | K57: 1113 | L57: 111 | M57: 11 | N57: 1 | O57: 1117 | P57: 113 | Q57: 11 | R57: 1
A58: =rebio23_80ml!A58 -> C-B-P07-H2 | B58: 113 | C58: 12 | D58: 1 | J58: 11118 | K58: 1113 | L58: 111 | M58: 11 | N58: 1 | O58: 1118 | P58: 113 | Q58: 11 | R58: 1
A59: =rebio23_80ml!A59 -> C-B-P07-H3 | B59: 113 | C59: 12 | D59: 1 | J59: 11119 | K59: 1113 | L59: 111 | M59: 11 | N59: 1 | O59: 1119 | P59: 113 | Q59: 11 | R59: 1
...

Sheet <-- AQUI
A1: Daqui para o lado esquerdo está correto e atualizado
